Workbook

Sheet SIMS
A1: PTB Project No | B1: PTB Description | C1: Collection Date | D1: Item No | E1: Serial No | G1: Client asset tag | H1: 3rd Party No / IMEI No | I1: Category | J1: Model | K1: Model No | L1: Purchase Description | N1: Diagnostic Codes | O1: Item Remark | P1: Grade | Q1: Item Status | R1: Weight (kg) | S1: Blancco Result | T1: Additional data deletions (if yes provide qty) | U1: Proposed Purchase price | V1: Currency
D2: ='Audit Report'!A2&"" -> ITD-SHR11556-W401 | E2: ='Audit Report'!B2&"" | G2: ='Audit Report'!C2&"" | I2: =_xlfn.XLOOKUP('Audit Report'!D2,Data!A:A,Data!B:B,'Audit Report'!D2)&"" | J2: ='Audit Report'!F2&"" | L2: =_xlfn.TEXTJOIN(", ", FALSE, 'Audit Report'!I2,'Audit Report'!J2,'Audit Report'!K2) -> , , | M2: ='Audit Report'!L2&"" | N2: {=IF(M2="","", _xlfn.TEXTJOIN(", ",TRUE, _xlfn.MAP(_xlfn.TEXTSPLIT(M2,","),_xlfn.LAMBDA(_xlpm.x, _xlfn.LET( _xlpm.item,TRIM(_xlpm.x), _xlpm.descCode, _xlfn.XLOOKUP(_xlpm.item,'Diagnostics Code'!$C$2:$C$500,'Diagnostics Code'!$B$2:$B$500,""), _xlpm.itadCode, IFERROR( INDEX('Diagnostics Code'!$B$2:$B$500, MATCH(TRUE, _xlfn.BYROW('Diagnostics Code'!$D$2:$D$500, _xlfn.LAMBDA(_xlpm.r,ISNUMBER(MATCH(_xlpm.item,TRIM(_xlfn.TEXTSPLIT(_xlpm.r,",")),0))) ), 0) ), ""), IF(_xlpm.descCode<>"",_xlpm.descCode,_xlpm.itadCode) ) )) ))} | R2: =_xlfn.XLOOKUP('Audit Report'!D2,Data!A:A,Data!C:C,"") | S2: ='Audit Report'!M2&""
D3: ='Audit Report'!A3&"" -> ITD-SHR11556-W402 | E3: ='Audit Report'!B3&"" | G3: ='Audit Report'!C3&"" | I3: =_xlfn.XLOOKUP('Audit Report'!D3,Data!A:A,Data!B:B,'Audit Report'!D3)&"" | J3: ='Audit Report'!F3&"" | L3: =_xlfn.TEXTJOIN(", ", FALSE, 'Audit Report'!I3,'Audit Report'!J3,'Audit Report'!K3) -> , , | M3: ='Audit Report'!L3&"" | N3: {=IF(M3="","", _xlfn.TEXTJOIN(", ",TRUE, _xlfn.MAP(_xlfn.TEXTSPLIT(M3,","),_xlfn.LAMBDA(_xlpm.x, _xlfn.LET( _xlpm.item,TRIM(_xlpm.x), _xlpm.descCode, _xlfn.XLOOKUP(_xlpm.item,'Diagnostics Code'!$C$2:$C$500,'Diagnostics Code'!$B$2:$B$500,""), _xlpm.itadCode, IFERROR( INDEX('Diagnostics Code'!$B$2:$B$500, MATCH(TRUE, _xlfn.BYROW('Diagnostics Code'!$D$2:$D$500, _xlfn.LAMBDA(_xlpm.r,ISNUMBER(MATCH(_xlpm.item,TRIM(_xlfn.TEXTSPLIT(_xlpm.r,",")),0))) ), 0) ), ""), IF(_xlpm.descCode<>"",_xlpm.descCode,_xlpm.itadCode) ) )) ))} | R3: =_xlfn.XLOOKUP('Audit Report'!D3,Data!A:A,Data!C:C,"") | S3: ='Audit Report'!M3&""
D4: ='Audit Report'!A4&"" -> ITD-SHR11556-W403 | E4: ='Audit Report'!B4&"" | G4: ='Audit Report'!C4&"" | I4: =_xlfn.XLOOKUP('Audit Report'!D4,Data!A:A,Data!B:B,'Audit Report'!D4)&"" | J4: ='Audit Report'!F4&"" | L4: =_xlfn.TEXTJOIN(", ", FALSE, 'Audit Report'!I4,'Audit Report'!J4,'Audit Report'!K4) -> , , | M4: ='Audit Report'!L4&"" | N4: {=IF(M4="","", _xlfn.TEXTJOIN(", ",TRUE, _xlfn.MAP(_xlfn.TEXTSPLIT(M4,","),_xlfn.LAMBDA(_xlpm.x, _xlfn.LET( _xlpm.item,TRIM(_xlpm.x), _xlpm.descCode, _xlfn.XLOOKUP(_xlpm.item,'Diagnostics Code'!$C$2:$C$500,'Diagnostics Code'!$B$2:$B$500,""), _xlpm.itadCode, IFERROR( INDEX('Diagnostics Code'!$B$2:$B$500, MATCH(TRUE, _xlfn.BYROW('Diagnostics Code'!$D$2:$D$500, _xlfn.LAMBDA(_xlpm.r,ISNUMBER(MATCH(_xlpm.item,TRIM(_xlfn.TEXTSPLIT(_xlpm.r,",")),0))) ), 0) ), ""), IF(_xlpm.descCode<>"",_xlpm.descCode,_xlpm.itadCode) ) )) ))} | R4: =_xlfn.XLOOKUP('Audit Report'!D4,Data!A:A,Data!C:C,"") | S4: ='Audit Report'!M4&""
D5: ='Audit Report'!A5&"" -> ITD-SHR11556-W404 | E5: ='Audit Report'!B5&"" | G5: ='Audit Report'!C5&"" | I5: =_xlfn.XLOOKUP('Audit Report'!D5,Data!A:A,Data!B:B,'Audit Report'!D5)&"" | J5: ='Audit Report'!F5&"" | L5: =_xlfn.TEXTJOIN(", ", FALSE, 'Audit Report'!I5,'Audit Report'!J5,'Audit Report'!K5) -> , , | M5: ='Audit Report'!L5&"" | N5: {=IF(M5="","", _xlfn.TEXTJOIN(", ",TRUE, _xlfn.MAP(_xlfn.TEXTSPLIT(M5,","),_xlfn.LAMBDA(_xlpm.x, _xlfn.LET( _xlpm.item,TRIM(_xlpm.x), _xlpm.descCode, _xlfn.XLOOKUP(_xlpm.item,'Diagnostics Code'!$C$2:$C$500,'Diagnostics Code'!$B$2:$B$500,""), _xlpm.itadCode, IFERROR( INDEX('Diagnostics Code'!$B$2:$B$500, MATCH(TRUE, _xlfn.BYROW('Diagnostics Code'!$D$2:$D$500, _xlfn.LAMBDA(_xlpm.r,ISNUMBER(MATCH(_xlpm.item,TRIM(_xlfn.TEXTSPLIT(_xlpm.r,",")),0))) ), 0) ), ""), IF(_xlpm.descCode<>"",_xlpm.descCode,_xlpm.itadCode) ) )) ))} | R5: =_xlfn.XLOOKUP('Audit Report'!D5,Data!A:A,Data!C:C,"") | S5: ='Audit Report'!M5&""
D6: ='Audit Report'!A6&"" -> ITD-SHR11556-W405 | E6: ='Audit Report'!B6&"" | G6: ='Audit Report'!C6&"" | I6: =_xlfn.XLOOKUP('Audit Report'!D6,Data!A:A,Data!B:B,'Audit Report'!D6)&"" | J6: ='Audit Report'!F6&"" | L6: =_xlfn.TEXTJOIN(", ", FALSE, 'Audit Report'!I6,'Audit Report'!J6,'Audit Report'!K6) -> , , | M6: ='Audit Report'!L6&"" | N6: {=IF(M6="","", _xlfn.TEXTJOIN(", ",TRUE, _xlfn.MAP(_xlfn.TEXTSPLIT(M6,","),_xlfn.LAMBDA(_xlpm.x, _xlfn.LET( _xlpm.item,TRIM(_xlpm.x), _xlpm.descCode, _xlfn.XLOOKUP(_xlpm.item,'Diagnostics Code'!$C$2:$C$500,'Diagnostics Code'!$B$2:$B$500,""), _xlpm.itadCode, IFERROR( INDEX('Diagnostics Code'!$B$2:$B$500, MATCH(TRUE, _xlfn.BYROW('Diagnostics Code'!$D$2:$D$500, _xlfn.LAMBDA(_xlpm.r,ISNUMBER(MATCH(_xlpm.item,TRIM(_xlfn.TEXTSPLIT(_xlpm.r,",")),0))) ), 0) ), ""), IF(_xlpm.descCode<>"",_xlpm.descCode,_xlpm.itadCode) ) )) ))} | R6: =_xlfn.XLOOKUP('Audit Report'!D6,Data!A:A,Data!C:C,"") | S6: ='Audit Report'!M6&""
D7: ='Audit Report'!A7&"" -> ITD-SHR11556-W406 | E7: ='Audit Report'!B7&"" | G7: ='Audit Report'!C7&"" | I7: =_xlfn.XLOOKUP('Audit Report'!D7,Data!A:A,Data!B:B,'Audit Report'!D7)&"" | J7: ='Audit Report'!F7&"" | L7: =_xlfn.TEXTJOIN(", ", FALSE, 'Audit Report'!I7,'Audit Report'!J7,'Audit Report'!K7) -> , , | M7: ='Audit Report'!L7&"" | N7: {=IF(M7="","", _xlfn.TEXTJOIN(", ",TRUE, _xlfn.MAP(_xlfn.TEXTSPLIT(M7,","),_xlfn.LAMBDA(_xlpm.x, _xlfn.LET( _xlpm.item,TRIM(_xlpm.x), _xlpm.descCode, _xlfn.XLOOKUP(_xlpm.item,'Diagnostics Code'!$C$2:$C$500,'Diagnostics Code'!$B$2:$B$500,""), _xlpm.itadCode, IFERROR( INDEX('Diagnostics Code'!$B$2:$B$500, MATCH(TRUE, _xlfn.BYROW('Diagnostics Code'!$D$2:$D$500, _xlfn.LAMBDA(_xlpm.r,ISNUMBER(MATCH(_xlpm.item,TRIM(_xlfn.TEXTSPLIT(_xlpm.r,",")),0))) ), 0) ), ""), IF(_xlpm.descCode<>"",_xlpm.descCode,_xlpm.itadCode) ) )) ))} | R7: =_xlfn.XLOOKUP('Audit Report'!D7,Data!A:A,Data!C:C,"") | S7: ='Audit Report'!M7&""
D8: ='Audit Report'!A8&"" -> ITD-SHR11556-W407 | E8: ='Audit Report'!B8&"" | G8: ='Audit Report'!C8&"" | I8: =_xlfn.XLOOKUP('Audit Report'!D8,Data!A:A,Data!B:B,'Audit Report'!D8)&"" | J8: ='Audit Report'!F8&"" | L8: =_xlfn.TEXTJOIN(", ", FALSE, 'Audit Report'!I8,'Audit Report'!J8,'Audit Report'!K8) -> , , | M8: ='Audit Report'!L8&"" | N8: {=IF(M8="","", _xlfn.TEXTJOIN(", ",TRUE, _xlfn.MAP(_xlfn.TEXTSPLIT(M8,","),_xlfn.LAMBDA(_xlpm.x, _xlfn.LET( _xlpm.item,TRIM(_xlpm.x), _xlpm.descCode, _xlfn.XLOOKUP(_xlpm.item,'Diagnostics Code'!$C$2:$C$500,'Diagnostics Code'!$B$2:$B$500,""), _xlpm.itadCode, IFERROR( INDEX('Diagnostics Code'!$B$2:$B$500, MATCH(TRUE, _xlfn.BYROW('Diagnostics Code'!$D$2:$D$500, _xlfn.LAMBDA(_xlpm.r,ISNUMBER(MATCH(_xlpm.item,TRIM(_xlfn.TEXTSPLIT(_xlpm.r,",")),0))) ), 0) ), ""), IF(_xlpm.descCode<>"",_xlpm.descCode,_xlpm.itadCode) ) )) ))} | R8: =_xlfn.XLOOKUP('Audit Report'!D8,Data!A:A,Data!C:C,"") | S8: ='Audit Report'!M8&""
D9: ='Audit Report'!A9&"" -> ITD-SHR11556-W408 | E9: ='Audit Report'!B9&"" | G9: ='Audit Report'!C9&"" | I9: =_xlfn.XLOOKUP('Audit Report'!D9,Data!A:A,Data!B:B,'Audit Report'!D9)&"" | J9: ='Audit Report'!F9&"" | L9: =_xlfn.TEXTJOIN(", ", FALSE, 'Audit Report'!I9,'Audit Report'!J9,'Audit Report'!K9) -> , , | M9: ='Audit Report'!L9&"" | N9: {=IF(M9="","", _xlfn.TEXTJOIN(", ",TRUE, _xlfn.MAP(_xlfn.TEXTSPLIT(M9,","),_xlfn.LAMBDA(_xlpm.x, _xlfn.LET( _xlpm.item,TRIM(_xlpm.x), _xlpm.descCode, _xlfn.XLOOKUP(_xlpm.item,'Diagnostics Code'!$C$2:$C$500,'Diagnostics Code'!$B$2:$B$500,""), _xlpm.itadCode, IFERROR( INDEX('Diagnostics Code'!$B$2:$B$500, MATCH(TRUE, _xlfn.BYROW('Diagnostics Code'!$D$2:$D$500, _xlfn.LAMBDA(_xlpm.r,ISNUMBER(MATCH(_xlpm.item,TRIM(_xlfn.TEXTSPLIT(_xlpm.r,",")),0))) ), 0) ), ""), IF(_xlpm.descCode<>"",_xlpm.descCode,_xlpm.itadCode) ) )) ))} | R9: =_xlfn.XLOOKUP('Audit Report'!D9,Data!A:A,Data!C:C,"") | S9: ='Audit Report'!M9&""
D10: ='Audit Report'!A10&"" -> ITD-SHR11556-W409 | E10: ='Audit Report'!B10&"" | G10: ='Audit Report'!C10&"" | I10: =_xlfn.XLOOKUP('Audit Report'!D10,Data!A:A,Data!B:B,'Audit Report'!D10)&"" | J10: ='Audit Report'!F10&"" | L10: =_xlfn.TEXTJOIN(", ", FALSE, 'Audit Report'!I10,'Audit Report'!J10,'Audit Report'!K10) -> , , | M10: ='Audit Report'!L10&"" | N10: {=IF(M10="","", _xlfn.TEXTJOIN(", ",TRUE, _xlfn.MAP(_xlfn.TEXTSPLIT(M10,","),_xlfn.LAMBDA(_xlpm.x, _xlfn.LET( _xlpm.item,TRIM(_xlpm.x), _xlpm.descCode, _xlfn.XLOOKUP(_xlpm.item,'Diagnostics Code'!$C$2:$C$500,'Diagnostics Code'!$B$2:$B$500,""), _xlpm.itadCode, IFERROR( INDEX('Diagnostics Code'!$B$2:$B$500, MATCH(TRUE, _xlfn.BYROW('Diagnostics Code'!$D$2:$D$500, _xlfn.LAMBDA(_xlpm.r,ISNUMBER(MATCH(_xlpm.item,TRIM(_xlfn.TEXTSPLIT(_xlpm.r,",")),0))) ), 0) ), ""), IF(_xlpm.descCode<>"",_xlpm.descCode,_xlpm.itadCode) ) )) ))} | R10: =_xlfn.XLOOKUP('Audit Report'!D10,Data!A:A,Data!C:C,"") | S10: ='Audit Report'!M10&""
D11: ='Audit Report'!A11&"" -> ITD-SHR11556-W410 | E11: ='Audit Report'!B11&"" | G11: ='Audit Report'!C11&"" | I11: =_xlfn.XLOOKUP('Audit Report'!D11,Data!A:A,Data!B:B,'Audit Report'!D11)&"" | J11: ='Audit Report'!F11&"" | L11: =_xlfn.TEXTJOIN(", ", FALSE, 'Audit Report'!I11,'Audit Report'!J11,'Audit Report'!K11) -> , , | M11: ='Audit Report'!L11&"" | N11: {=IF(M11="","", _xlfn.TEXTJOIN(", ",TRUE, _xlfn.MAP(_xlfn.TEXTSPLIT(M11,","),_xlfn.LAMBDA(_xlpm.x, _xlfn.LET( _xlpm.item,TRIM(_xlpm.x), _xlpm.descCode, _xlfn.XLOOKUP(_xlpm.item,'Diagnostics Code'!$C$2:$C$500,'Diagnostics Code'!$B$2:$B$500,""), _xlpm.itadCode, IFERROR( INDEX('Diagnostics Code'!$B$2:$B$500, MATCH(TRUE, _xlfn.BYROW('Diagnostics Code'!$D$2:$D$500, _xlfn.LAMBDA(_xlpm.r,ISNUMBER(MATCH(_xlpm.item,TRIM(_xlfn.TEXTSPLIT(_xlpm.r,",")),0))) ), 0) ), ""), IF(_xlpm.descCode<>"",_xlpm.descCode,_xlpm.itadCode) ) )) ))} | R11: =_xlfn.XLOOKUP('Audit Report'!D11,Data!A:A,Data!C:C,"") | S11: ='Audit Report'!M11&""
D12: ='Audit Report'!A12&"" -> ITD-SHR11556-W411 | E12: ='Audit Report'!B12&"" | G12: ='Audit Report'!C12&"" | I12: =_xlfn.XLOOKUP('Audit Report'!D12,Data!A:A,Data!B:B,'Audit Report'!D12)&"" | J12: ='Audit Report'!F12&"" | L12: =_xlfn.TEXTJOIN(", ", FALSE, 'Audit Report'!I12,'Audit Report'!J12,'Audit Report'!K12) -> , , | M12: ='Audit Report'!L12&"" | N12: {=IF(M12="","", _xlfn.TEXTJOIN(", ",TRUE, _xlfn.MAP(_xlfn.TEXTSPLIT(M12,","),_xlfn.LAMBDA(_xlpm.x, _xlfn.LET( _xlpm.item,TRIM(_xlpm.x), _xlpm.descCode, _xlfn.XLOOKUP(_xlpm.item,'Diagnostics Code'!$C$2:$C$500,'Diagnostics Code'!$B$2:$B$500,""), _xlpm.itadCode, IFERROR( INDEX('Diagnostics Code'!$B$2:$B$500, MATCH(TRUE, _xlfn.BYROW('Diagnostics Code'!$D$2:$D$500, _xlfn.LAMBDA(_xlpm.r,ISNUMBER(MATCH(_xlpm.item,TRIM(_xlfn.TEXTSPLIT(_xlpm.r,",")),0))) ), 0) ), ""), IF(_xlpm.descCode<>"",_xlpm.descCode,_xlpm.itadCode) ) )) ))} | R12: =_xlfn.XLOOKUP('Audit Report'!D12,Data!A:A,Data!C:C,"") | S12: ='Audit Report'!M12&""
D13: ='Audit Report'!A13&"" -> ITD-SHR11556-W412 | E13: ='Audit Report'!B13&"" | G13: ='Audit Report'!C13&"" | I13: =_xlfn.XLOOKUP('Audit Report'!D13,Data!A:A,Data!B:B,'Audit Report'!D13)&"" | J13: ='Audit Report'!F13&"" | L13: =_xlfn.TEXTJOIN(", ", FALSE, 'Audit Report'!I13,'Audit Report'!J13,'Audit Report'!K13) -> , , | M13: ='Audit Report'!L13&"" | N13: {=IF(M13="","", _xlfn.TEXTJOIN(", ",TRUE, _xlfn.MAP(_xlfn.TEXTSPLIT(M13,","),_xlfn.LAMBDA(_xlpm.x, _xlfn.LET( _xlpm.item,TRIM(_xlpm.x), _xlpm.descCode, _xlfn.XLOOKUP(_xlpm.item,'Diagnostics Code'!$C$2:$C$500,'Diagnostics Code'!$B$2:$B$500,""), _xlpm.itadCode, IFERROR( INDEX('Diagnostics Code'!$B$2:$B$500, MATCH(TRUE, _xlfn.BYROW('Diagnostics Code'!$D$2:$D$500, _xlfn.LAMBDA(_xlpm.r,ISNUMBER(MATCH(_xlpm.item,TRIM(_xlfn.TEXTSPLIT(_xlpm.r,",")),0))) ), 0) ), ""), IF(_xlpm.descCode<>"",_xlpm.descCode,_xlpm.itadCode) ) )) ))} | R13: =_xlfn.XLOOKUP('Audit Report'!D13,Data!A:A,Data!C:C,"") | S13: ='Audit Report'!M13&""
... D382: ='Audit Report'!A382&"" -> ITD-SHR11556-W4381 | E382: ='Audit Report'!B382&"" | G382: ='Audit Report'!C382&"" | I382: =_xlfn.XLOOKUP('Audit Report'!D382,Data!A:A,Data!B:B,'Audit Report'!D382)&"" | J382: ='Audit Report'!F382&"" | L382: =_xlfn.TEXTJOIN(", ", FALSE, 'Audit Report'!I382,'Audit Report'!J382,'Audit Report'!K382) -> , , | M382: ='Audit Report'!L382&"" | N382: {=IF(M382="","", _xlfn.TEXTJOIN(", ",TRUE, _xlfn.MAP(_xlfn.TEXTSPLIT(M382,","),_xlfn.LAMBDA(_xlpm.x, _xlfn.LET( _xlpm.item,TRIM(_xlpm.x), _xlpm.descCode, _xlfn.XLOOKUP(_xlpm.item,'Diagnostics Code'!$C$2:$C$500,'Diagnostics Code'!$B$2:$B$500,""), _xlpm.itadCode, IFERROR( INDEX('Diagnostics Code'!$B$2:$B$500, MATCH(TRUE, _xlfn.BYROW('Diagnostics Code'!$D$2:$D$500, _xlfn.LAMBDA(_xlpm.r,ISNUMBER(MATCH(_xlpm.item,TRIM(_xlfn.TEXTSPLIT(_xlpm.r,",")),0))) ), 0) ), ""), IF(_xlpm.descCode<>"",_xlpm.descCode,_xlpm.itadCode) ) )) ))} | R382: =_xlfn.XLOOKUP('Audit Report'!D382,Data!A:A,Data!C:C,"") | S382: ='Audit Report'!M382&""
D383: ='Audit Report'!A383&"" -> ITD-SHR11556-W4382 | E383: ='Audit Report'!B383&"" | G383: ='Audit Report'!C383&"" | I383: =_xlfn.XLOOKUP('Audit Report'!D383,Data!A:A,Data!B:B,'Audit Report'!D383)&"" | J383: ='Audit Report'!F383&"" | L383: =_xlfn.TEXTJOIN(", ", FALSE, 'Audit Report'!I383,'Audit Report'!J383,'Audit Report'!K383) -> , , | M383: ='Audit Report'!L383&"" | N383: {=IF(M383="","", _xlfn.TEXTJOIN(", ",TRUE, _xlfn.MAP(_xlfn.TEXTSPLIT(M383,","),_xlfn.LAMBDA(_xlpm.x, _xlfn.LET( _xlpm.item,TRIM(_xlpm.x), _xlpm.descCode, _xlfn.XLOOKUP(_xlpm.item,'Diagnostics Code'!$C$2:$C$500,'Diagnostics Code'!$B$2:$B$500,""), _xlpm.itadCode, IFERROR( INDEX('Diagnostics Code'!$B$2:$B$500, MATCH(TRUE, _xlfn.BYROW('Diagnostics Code'!$D$2:$D$500, _xlfn.LAMBDA(_xlpm.r,ISNUMBER(MATCH(_xlpm.item,TRIM(_xlfn.TEXTSPLIT(_xlpm.r,",")),0))) ), 0) ), ""), IF(_xlpm.descCode<>"",_xlpm.descCode,_xlpm.itadCode) ) )) ))} | R383: =_xlfn.XLOOKUP('Audit Report'!D383,Data!A:A,Data!C:C) -> #N/A | S383: ='Audit Report'!M383&""
D384: ='Audit Report'!A384&"" -> ITD-SHR11556-W4383 | E384: ='Audit Report'!B384&"" | G384: ='Audit Report'!C384&"" | I384: =_xlfn.XLOOKUP('Audit Report'!D384,Data!A:A,Data!B:B,'Audit Report'!D384)&"" | J384: ='Audit Report'!F384&"" | L384: =_xlfn.TEXTJOIN(", ", FALSE, 'Audit Report'!I384,'Audit Report'!J384,'Audit Report'!K384) -> , , | M384: ='Audit Report'!L384&"" | N384: {=IF(M384="","", _xlfn.TEXTJOIN(", ",TRUE, _xlfn.MAP(_xlfn.TEXTSPLIT(M384,","),_xlfn.LAMBDA(_xlpm.x, _xlfn.LET( _xlpm.item,TRIM(_xlpm.x), _xlpm.descCode, _xlfn.XLOOKUP(_xlpm.item,'Diagnostics Code'!$C$2:$C$500,'Diagnostics Code'!$B$2:$B$500,""), _xlpm.itadCode, IFERROR( INDEX('Diagnostics Code'!$B$2:$B$500, MATCH(TRUE, _xlfn.BYROW('Diagnostics Code'!$D$2:$D$500, _xlfn.LAMBDA(_xlpm.r,ISNUMBER(MATCH(_xlpm.item,TRIM(_xlfn.TEXTSPLIT(_xlpm.r,",")),0))) ), 0) ), ""), IF(_xlpm.descCode<>"",_xlpm.descCode,_xlpm.itadCode) ) )) ))} | R384: =_xlfn.XLOOKUP('Audit Report'!D384,Data!A:A,Data!C:C) -> #N/A | S384: ='Audit Report'!M384&""
D385: ='Audit Report'!A385&"" -> ITD-SHR11556-W4384 | E385: ='Audit Report'!B385&"" | G385: ='Audit Report'!C385&"" | I385: =_xlfn.XLOOKUP('Audit Report'!D385,Data!A:A,Data!B:B,'Audit Report'!D385)&"" | J385: ='Audit Report'!F385&"" | L385: =_xlfn.TEXTJOIN(", ", FALSE, 'Audit Report'!I385,'Audit Report'!J385,'Audit Report'!K385) -> , , | M385: ='Audit Report'!L385&"" | N385: {=IF(M385="","", _xlfn.TEXTJOIN(", ",TRUE, _xlfn.MAP(_xlfn.TEXTSPLIT(M385,","),_xlfn.LAMBDA(_xlpm.x, _xlfn.LET( _xlpm.item,TRIM(_xlpm.x), _xlpm.descCode, _xlfn.XLOOKUP(_xlpm.item,'Diagnostics Code'!$C$2:$C$500,'Diagnostics Code'!$B$2:$B$500,""), _xlpm.itadCode, IFERROR( INDEX('Diagnostics Code'!$B$2:$B$500, MATCH(TRUE, _xlfn.BYROW('Diagnostics Code'!$D$2:$D$500, _xlfn.LAMBDA(_xlpm.r,ISNUMBER(MATCH(_xlpm.item,TRIM(_xlfn.TEXTSPLIT(_xlpm.r,",")),0))) ), 0) ), ""), IF(_xlpm.descCode<>"",_xlpm.descCode,_xlpm.itadCode) ) )) ))} | R385: =_xlfn.XLOOKUP('Audit Report'!D385,Data!A:A,Data!C:C) -> #N/A | S385: ='Audit Report'!M385&""
D386: ='Audit Report'!A386&"" -> ITD-SHR11556-W4385 | E386: ='Audit Report'!B386&"" | G386: ='Audit Report'!C386&"" | I386: =_xlfn.XLOOKUP('Audit Report'!D386,Data!A:A,Data!B:B,'Audit Report'!D386)&"" | J386: ='Audit Report'!F386&"" | L386: =_xlfn.TEXTJOIN(", ", FALSE, 'Audit Report'!I386,'Audit Report'!J386,'Audit Report'!K386) -> , , | M386: ='Audit Report'!L386&"" | N386: {=IF(M386="","", _xlfn.TEXTJOIN(", ",TRUE, _xlfn.MAP(_xlfn.TEXTSPLIT(M386,","),_xlfn.LAMBDA(_xlpm.x, _xlfn.LET( _xlpm.item,TRIM(_xlpm.x), _xlpm.descCode, _xlfn.XLOOKUP(_xlpm.item,'Diagnostics Code'!$C$2:$C$500,'Diagnostics Code'!$B$2:$B$500,""), _xlpm.itadCode, IFERROR( INDEX('Diagnostics Code'!$B$2:$B$500, MATCH(TRUE, _xlfn.BYROW('Diagnostics Code'!$D$2:$D$500, _xlfn.LAMBDA(_xlpm.r,ISNUMBER(MATCH(_xlpm.item,TRIM(_xlfn.TEXTSPLIT(_xlpm.r,",")),0))) ), 0) ), ""), IF(_xlpm.descCode<>"",_xlpm.descCode,_xlpm.itadCode) ) )) ))} | R386: =_xlfn.XLOOKUP('Audit Report'!D386,Data!A:A,Data!C:C) -> #N/A | S386: ='Audit Report'!M386&""
D387: ='Audit Report'!A387&"" -> ITD-SHR11556-W4386 | E387: ='Audit Report'!B387&"" | G387: ='Audit Report'!C387&"" | I387: =_xlfn.XLOOKUP('Audit Report'!D387,Data!A:A,Data!B:B,'Audit Report'!D387)&"" | J387: ='Audit Report'!F387&"" | L387: =_xlfn.TEXTJOIN(", ", FALSE, 'Audit Report'!I387,'Audit Report'!J387,'Audit Report'!K387) -> , , | M387: ='Audit Report'!L387&"" | N387: {=IF(M387="","", _xlfn.TEXTJOIN(", ",TRUE, _xlfn.MAP(_xlfn.TEXTSPLIT(M387,","),_xlfn.LAMBDA(_xlpm.x, _xlfn.LET( _xlpm.item,TRIM(_xlpm.x), _xlpm.descCode, _xlfn.XLOOKUP(_xlpm.item,'Diagnostics Code'!$C$2:$C$500,'Diagnostics Code'!$B$2:$B$500,""), _xlpm.itadCode, IFERROR( INDEX('Diagnostics Code'!$B$2:$B$500, MATCH(TRUE, _xlfn.BYROW('Diagnostics Code'!$D$2:$D$500, _xlfn.LAMBDA(_xlpm.r,ISNUMBER(MATCH(_xlpm.item,TRIM(_xlfn.TEXTSPLIT(_xlpm.r,",")),0))) ), 0) ), ""), IF(_xlpm.descCode<>"",_xlpm.descCode,_xlpm.itadCode) ) )) ))} | R387: =_xlfn.XLOOKUP('Audit Report'!D387,Data!A:A,Data!C:C) -> #N/A | S387: ='Audit Report'!M387&""
D388: ='Audit Report'!A388&"" -> ITD-SHR11556-W4387 | E388: ='Audit Report'!B388&"" | G388: ='Audit Report'!C388&"" | I388: =_xlfn.XLOOKUP('Audit Report'!D388,Data!A:A,Data!B:B,'Audit Report'!D388)&"" | J388: ='Audit Report'!F388&"" | L388: =_xlfn.TEXTJOIN(", ", FALSE, 'Audit Report'!I388,'Audit Report'!J388,'Audit Report'!K388) -> , , | M388: ='Audit Report'!L388&"" | N388: {=IF(M388="","", _xlfn.TEXTJOIN(", ",TRUE, _xlfn.MAP(_xlfn.TEXTSPLIT(M388,","),_xlfn.LAMBDA(_xlpm.x, _xlfn.LET( _xlpm.item,TRIM(_xlpm.x), _xlpm.descCode, _xlfn.XLOOKUP(_xlpm.item,'Diagnostics Code'!$C$2:$C$500,'Diagnostics Code'!$B$2:$B$500,""), _xlpm.itadCode, IFERROR( INDEX('Diagnostics Code'!$B$2:$B$500, MATCH(TRUE, _xlfn.BYROW('Diagnostics Code'!$D$2:$D$500, _xlfn.LAMBDA(_xlpm.r,ISNUMBER(MATCH(_xlpm.item,TRIM(_xlfn.TEXTSPLIT(_xlpm.r,",")),0))) ), 0) ), ""), IF(_xlpm.descCode<>"",_xlpm.descCode,_xlpm.itadCode) ) )) ))} | R388: =_xlfn.XLOOKUP('Audit Report'!D388,Data!A:A,Data!C:C) -> #N/A | S388: ='Audit Report'!M388&""
D389: ='Audit Report'!A389&"" -> ITD-SHR11556-W4388 | E389: ='Audit Report'!B389&"" | G389: ='Audit Report'!C389&"" | I389: =_xlfn.XLOOKUP('Audit Report'!D389,Data!A:A,Data!B:B,'Audit Report'!D389)&"" | J389: ='Audit Report'!F389&"" | L389: =_xlfn.TEXTJOIN(", ", FALSE, 'Audit Report'!I389,'Audit Report'!J389,'Audit Report'!K389) -> , , | M389: ='Audit Report'!L389&"" | N389: {=IF(M389="","", _xlfn.TEXTJOIN(", ",TRUE, _xlfn.MAP(_xlfn.TEXTSPLIT(M389,","),_xlfn.LAMBDA(_xlpm.x, _xlfn.LET( _xlpm.item,TRIM(_xlpm.x), _xlpm.descCode, _xlfn.XLOOKUP(_xlpm.item,'Diagnostics Code'!$C$2:$C$500,'Diagnostics Code'!$B$2:$B$500,""), _xlpm.itadCode, IFERROR( INDEX('Diagnostics Code'!$B$2:$B$500, MATCH(TRUE, _xlfn.BYROW('Diagnostics Code'!$D$2:$D$500, _xlfn.LAMBDA(_xlpm.r,ISNUMBER(MATCH(_xlpm.item,TRIM(_xlfn.TEXTSPLIT(_xlpm.r,",")),0))) ), 0) ), ""), IF(_xlpm.descCode<>"",_xlpm.descCode,_xlpm.itadCode) ) )) ))} | R389: =_xlfn.XLOOKUP('Audit Report'!D389,Data!A:A,Data!C:C) -> #N/A | S389: ='Audit Report'!M389&""
D390: ='Audit Report'!A390&"" -> ITD-SHR11556-W4389 | E390: ='Audit Report'!B390&"" | G390: ='Audit Report'!C390&"" | I390: =_xlfn.XLOOKUP('Audit Report'!D390,Data!A:A,Data!B:B,'Audit Report'!D390)&"" | J390: ='Audit Report'!F390&"" | L390: =_xlfn.TEXTJOIN(", ", FALSE, 'Audit Report'!I390,'Audit Report'!J390,'Audit Report'!K390) -> , , | M390: ='Audit Report'!L390&"" | N390: {=IF(M390="","", _xlfn.TEXTJOIN(", ",TRUE, _xlfn.MAP(_xlfn.TEXTSPLIT(M390,","),_xlfn.LAMBDA(_xlpm.x, _xlfn.LET( _xlpm.item,TRIM(_xlpm.x), _xlpm.descCode, _xlfn.XLOOKUP(_xlpm.item,'Diagnostics Code'!$C$2:$C$500,'Diagnostics Code'!$B$2:$B$500,""), _xlpm.itadCode, IFERROR( INDEX('Diagnostics Code'!$B$2:$B$500, MATCH(TRUE, _xlfn.BYROW('Diagnostics Code'!$D$2:$D$500, _xlfn.LAMBDA(_xlpm.r,ISNUMBER(MATCH(_xlpm.item,TRIM(_xlfn.TEXTSPLIT(_xlpm.r,",")),0))) ), 0) ), ""), IF(_xlpm.descCode<>"",_xlpm.descCode,_xlpm.itadCode) ) )) ))} | R390: =_xlfn.XLOOKUP('Audit Report'!D390,Data!A:A,Data!C:C) -> #N/A | S390: ='Audit Report'!M390&""
D391: ='Audit Report'!A391&"" -> ITD-SHR11556-W4390 | E391: ='Audit Report'!B391&"" | G391: ='Audit Report'!C391&"" | I391: =_xlfn.XLOOKUP('Audit Report'!D391,Data!A:A,Data!B:B,'Audit Report'!D391)&"" | J391: ='Audit Report'!F391&"" | L391: =_xlfn.TEXTJOIN(", ", FALSE, 'Audit Report'!I391,'Audit Report'!J391,'Audit Report'!K391) -> , , | M391: ='Audit Report'!L391&"" | N391: {=IF(M391="","", _xlfn.TEXTJOIN(", ",TRUE, _xlfn.MAP(_xlfn.TEXTSPLIT(M391,","),_xlfn.LAMBDA(_xlpm.x, _xlfn.LET( _xlpm.item,TRIM(_xlpm.x), _xlpm.descCode, _xlfn.XLOOKUP(_xlpm.item,'Diagnostics Code'!$C$2:$C$500,'Diagnostics Code'!$B$2:$B$500,""), _xlpm.itadCode, IFERROR( INDEX('Diagnostics Code'!$B$2:$B$500, MATCH(TRUE, _xlfn.BYROW('Diagnostics Code'!$D$2:$D$500, _xlfn.LAMBDA(_xlpm.r,ISNUMBER(MATCH(_xlpm.item,TRIM(_xlfn.TEXTSPLIT(_xlpm.r,",")),0))) ), 0) ), ""), IF(_xlpm.descCode<>"",_xlpm.descCode,_xlpm.itadCode) ) )) ))} | R391: =_xlfn.XLOOKUP('Audit Report'!D391,Data!A:A,Data!C:C) -> #N/A | S391: ='Audit Report'!M391&""
D392: ='Audit Report'!A392&"" -> ITD-SHR11556-W4391 | E392: ='Audit Report'!B392&"" | G392: ='Audit Report'!C392&"" | I392: =_xlfn.XLOOKUP('Audit Report'!D392,Data!A:A,Data!B:B,'Audit Report'!D392)&"" | J392: ='Audit Report'!F392&"" | L392: =_xlfn.TEXTJOIN(", ", FALSE, 'Audit Report'!I392,'Audit Report'!J392,'Audit Report'!K392) -> , , | M392: ='Audit Report'!L392&"" | N392: {=IF(M392="","", _xlfn.TEXTJOIN(", ",TRUE, _xlfn.MAP(_xlfn.TEXTSPLIT(M392,","),_xlfn.LAMBDA(_xlpm.x, _xlfn.LET( _xlpm.item,TRIM(_xlpm.x), _xlpm.descCode, _xlfn.XLOOKUP(_xlpm.item,'Diagnostics Code'!$C$2:$C$500,'Diagnostics Code'!$B$2:$B$500,""), _xlpm.itadCode, IFERROR( INDEX('Diagnostics Code'!$B$2:$B$500, MATCH(TRUE, _xlfn.BYROW('Diagnostics Code'!$D$2:$D$500, _xlfn.LAMBDA(_xlpm.r,ISNUMBER(MATCH(_xlpm.item,TRIM(_xlfn.TEXTSPLIT(_xlpm.r,",")),0))) ), 0) ), ""), IF(_xlpm.descCode<>"",_xlpm.descCode,_xlpm.itadCode) ) )) ))} | R392: =_xlfn.XLOOKUP('Audit Report'!D392,Data!A:A,Data!C:C) -> #N/A | S392: ='Audit Report'!M392&""
D393: ='Audit Report'!A393&"" -> ITD-SHR11556-W4392 | E393: ='Audit Report'!B393&"" | G393: ='Audit Report'!C393&"" | I393: =_xlfn.XLOOKUP('Audit Report'!D393,Data!A:A,Data!B:B,'Audit Report'!D393)&"" | J393: ='Audit Report'!F393&"" | L393: =_xlfn.TEXTJOIN(", ", FALSE, 'Audit Report'!I393,'Audit Report'!J393,'Audit Report'!K393) -> , , | M393: ='Audit Report'!L393&"" | N393: {=IF(M393="","", _xlfn.TEXTJOIN(", ",TRUE, _xlfn.MAP(_xlfn.TEXTSPLIT(M393,","),_xlfn.LAMBDA(_xlpm.x, _xlfn.LET( _xlpm.item,TRIM(_xlpm.x), _xlpm.descCode, _xlfn.XLOOKUP(_xlpm.item,'Diagnostics Code'!$C$2:$C$500,'Diagnostics Code'!$B$2:$B$500,""), _xlpm.itadCode, IFERROR( INDEX('Diagnostics Code'!$B$2:$B$500, MATCH(TRUE, _xlfn.BYROW('Diagnostics Code'!$D$2:$D$500, _xlfn.LAMBDA(_xlpm.r,ISNUMBER(MATCH(_xlpm.item,TRIM(_xlfn.TEXTSPLIT(_xlpm.r,",")),0))) ), 0) ), ""), IF(_xlpm.descCode<>"",_xlpm.descCode,_xlpm.itadCode) ) )) ))} | R393: =_xlfn.XLOOKUP('Audit Report'!D393,Data!A:A,Data!C:C) -> #N/A | S393: ='Audit Report'!M393&""
D394: ='Audit Report'!A394&"" -> ITD-SHR11556-W4393 | E394: ='Audit Report'!B394&"" | G394: ='Audit Report'!C394&"" | I394: =_xlfn.XLOOKUP('Audit Report'!D394,Data!A:A,Data!B:B,'Audit Report'!D394)&"" | J394: ='Audit Report'!F394&"" | L394: =_xlfn.TEXTJOIN(", ", FALSE, 'Audit Report'!I394,'Audit Report'!J394,'Audit Report'!K394) -> , , | M394: ='Audit Report'!L394&"" | N394: {=IF(M394="","", _xlfn.TEXTJOIN(", ",TRUE, _xlfn.MAP(_xlfn.TEXTSPLIT(M394,","),_xlfn.LAMBDA(_xlpm.x, _xlfn.LET( _xlpm.item,TRIM(_xlpm.x), _xlpm.descCode, _xlfn.XLOOKUP(_xlpm.item,'Diagnostics Code'!$C$2:$C$500,'Diagnostics Code'!$B$2:$B$500,""), _xlpm.itadCode, IFERROR( INDEX('Diagnostics Code'!$B$2:$B$500, MATCH(TRUE, _xlfn.BYROW('Diagnostics Code'!$D$2:$D$500, _xlfn.LAMBDA(_xlpm.r,ISNUMBER(MATCH(_xlpm.item,TRIM(_xlfn.TEXTSPLIT(_xlpm.r,",")),0))) ), 0) ), ""), IF(_xlpm.descCode<>"",_xlpm.descCode,_xlpm.itadCode) ) )) ))} | R394: =_xlfn.XLOOKUP('Audit Report'!D394,Data!A:A,Data!C:C) -> #N/A | S394: ='Audit Report'!M394&""
... D539: ='Audit Report'!A539&"" -> ITD-SHR11556-W4538 | E539: ='Audit Report'!B539&"" | G539: ='Audit Report'!C539&"" | I539: =_xlfn.XLOOKUP('Audit Report'!D539,Data!A:A,Data!B:B,'Audit Report'!D539)&"" | J539: ='Audit Report'!F539&"" | L539: =_xlfn.TEXTJOIN(", ", FALSE, 'Audit Report'!I539,'Audit Report'!J539,'Audit Report'!K539) -> , , | M539: ='Audit Report'!L539&"" | N539: {=IF(M539="","", _xlfn.TEXTJOIN(", ",TRUE, _xlfn.MAP(_xlfn.TEXTSPLIT(M539,","),_xlfn.LAMBDA(_xlpm.x, _xlfn.LET( _xlpm.item,TRIM(_xlpm.x), _xlpm.descCode, _xlfn.XLOOKUP(_xlpm.item,'Diagnostics Code'!$C$2:$C$500,'Diagnostics Code'!$B$2:$B$500,""), _xlpm.itadCode, IFERROR( INDEX('Diagnostics Code'!$B$2:$B$500, MATCH(TRUE, _xlfn.BYROW('Diagnostics Code'!$D$2:$D$500, _xlfn.LAMBDA(_xlpm.r,ISNUMBER(MATCH(_xlpm.item,TRIM(_xlfn.TEXTSPLIT(_xlpm.r,",")),0))) ), 0) ), ""), IF(_xlpm.descCode<>"",_xlpm.descCode,_xlpm.itadCode) ) )) ))} | R539: =_xlfn.XLOOKUP('Audit Report'!D539,Data!A:A,Data!C:C) -> #N/A | S539: ='Audit Report'!M539&""
D540: ='Audit Report'!A540&"" -> ITD-SHR11556-W4539 | E540: ='Audit Report'!B540&"" | G540: ='Audit Report'!C540&"" | I540: =_xlfn.XLOOKUP('Audit Report'!D540,Data!A:A,Data!B:B,'Audit Report'!D540)&"" | J540: ='Audit Report'!F540&"" | L540: =_xlfn.TEXTJOIN(", ", FALSE, 'Audit Report'!I540,'Audit Report'!J540,'Audit Report'!K540) -> , , | M540: ='Audit Report'!L540&"" | N540: {=IF(M540="","", _xlfn.TEXTJOIN(", ",TRUE, _xlfn.MAP(_xlfn.TEXTSPLIT(M540,","),_xlfn.LAMBDA(_xlpm.x, _xlfn.LET( _xlpm.item,TRIM(_xlpm.x), _xlpm.descCode, _xlfn.XLOOKUP(_xlpm.item,'Diagnostics Code'!$C$2:$C$500,'Diagnostics Code'!$B$2:$B$500,""), _xlpm.itadCode, IFERROR( INDEX('Diagnostics Code'!$B$2:$B$500, MATCH(TRUE, _xlfn.BYROW('Diagnostics Code'!$D$2:$D$500, _xlfn.LAMBDA(_xlpm.r,ISNUMBER(MATCH(_xlpm.item,TRIM(_xlfn.TEXTSPLIT(_xlpm.r,",")),0))) ), 0) ), ""), IF(_xlpm.descCode<>"",_xlpm.descCode,_xlpm.itadCode) ) )) ))} | R540: =_xlfn.XLOOKUP('Audit Report'!D540,Data!A:A,Data!C:C) -> #N/A | S540: ='[1]Audit Report'!N540
D541: ='Audit Report'!A541&"" -> ITD-SHR11556-W4540 | E541: ='Audit Report'!B541&"" | G541: ='Audit Report'!C541&"" | I541: =_xlfn.XLOOKUP('Audit Report'!D541,Data!A:A,Data!B:B,'Audit Report'!D541)&"" | J541: ='Audit Report'!F541&"" | L541: =_xlfn.TEXTJOIN(", ", FALSE, 'Audit Report'!I541,'Audit Report'!J541,'Audit Report'!K541) -> , , | M541: ='Audit Report'!L541&"" | N541: {=IF(M541="","", _xlfn.TEXTJOIN(", ",TRUE, _xlfn.MAP(_xlfn.TEXTSPLIT(M541,","),_xlfn.LAMBDA(_xlpm.x, _xlfn.LET( _xlpm.item,TRIM(_xlpm.x), _xlpm.descCode, _xlfn.XLOOKUP(_xlpm.item,'Diagnostics Code'!$C$2:$C$500,'Diagnostics Code'!$B$2:$B$500,""), _xlpm.itadCode, IFERROR( INDEX('Diagnostics Code'!$B$2:$B$500, MATCH(TRUE, _xlfn.BYROW('Diagnostics Code'!$D$2:$D$500, _xlfn.LAMBDA(_xlpm.r,ISNUMBER(MATCH(_xlpm.item,TRIM(_xlfn.TEXTSPLIT(_xlpm.r,",")),0))) ), 0) ), ""), IF(_xlpm.descCode<>"",_xlpm.descCode,_xlpm.itadCode) ) )) ))} | R541: =_xlfn.XLOOKUP('Audit Report'!D541,Data!A:A,Data!C:C) -> #N/A | S541: ='[1]Audit Report'!N541
D542: ='Audit Report'!A542&"" -> ITD-SHR11556-W4541 | E542: ='Audit Report'!B542&"" | G542: ='Audit Report'!C542&"" | I542: =_xlfn.XLOOKUP('Audit Report'!D542,Data!A:A,Data!B:B,'Audit Report'!D542)&"" | J542: ='Audit Report'!F542&"" | L542: =_xlfn.TEXTJOIN(", ", FALSE, 'Audit Report'!I542,'Audit Report'!J542,'Audit Report'!K542) -> , , | M542: ='Audit Report'!L542&"" | N542: {=IF(M542="","", _xlfn.TEXTJOIN(", ",TRUE, _xlfn.MAP(_xlfn.TEXTSPLIT(M542,","),_xlfn.LAMBDA(_xlpm.x, _xlfn.LET( _xlpm.item,TRIM(_xlpm.x), _xlpm.descCode, _xlfn.XLOOKUP(_xlpm.item,'Diagnostics Code'!$C$2:$C$500,'Diagnostics Code'!$B$2:$B$500,""), _xlpm.itadCode, IFERROR( INDEX('Diagnostics Code'!$B$2:$B$500, MATCH(TRUE, _xlfn.BYROW('Diagnostics Code'!$D$2:$D$500, _xlfn.LAMBDA(_xlpm.r,ISNUMBER(MATCH(_xlpm.item,TRIM(_xlfn.TEXTSPLIT(_xlpm.r,",")),0))) ), 0) ), ""), IF(_xlpm.descCode<>"",_xlpm.descCode,_xlpm.itadCode) ) )) ))} | R542: =_xlfn.XLOOKUP('Audit Report'!D542,Data!A:A,Data!C:C) -> #N/A | S542: ='[1]Audit Report'!N542
D543: ='Audit Report'!A543&"" -> ITD-SHR11556-W4542 | E543: ='Audit Report'!B543&"" | G543: ='Audit Report'!C543&"" | I543: =_xlfn.XLOOKUP('Audit Report'!D543,Data!A:A,Data!B:B,'Audit Report'!D543)&"" | J543: ='Audit Report'!F543&"" | L543: =_xlfn.TEXTJOIN(", ", FALSE, 'Audit Report'!I543,'Audit Report'!J543,'Audit Report'!K543) -> , , | M543: ='Audit Report'!L543&"" | N543: {=IF(M543="","", _xlfn.TEXTJOIN(", ",TRUE, _xlfn.MAP(_xlfn.TEXTSPLIT(M543,","),_xlfn.LAMBDA(_xlpm.x, _xlfn.LET( _xlpm.item,TRIM(_xlpm.x), _xlpm.descCode, _xlfn.XLOOKUP(_xlpm.item,'Diagnostics Code'!$C$2:$C$500,'Diagnostics Code'!$B$2:$B$500,""), _xlpm.itadCode, IFERROR( INDEX('Diagnostics Code'!$B$2:$B$500, MATCH(TRUE, _xlfn.BYROW('Diagnostics Code'!$D$2:$D$500, _xlfn.LAMBDA(_xlpm.r,ISNUMBER(MATCH(_xlpm.item,TRIM(_xlfn.TEXTSPLIT(_xlpm.r,",")),0))) ), 0) ), ""), IF(_xlpm.descCode<>"",_xlpm.descCode,_xlpm.itadCode) ) )) ))} | R543: =_xlfn.XLOOKUP('Audit Report'!D543,Data!A:A,Data!C:C) -> #N/A | S543: ='[1]Audit Report'!N543
D544: ='Audit Report'!A544&"" -> ITD-SHR11556-W4543 | E544: ='Audit Report'!B544&"" | G544: ='Audit Report'!C544&"" | I544: =_xlfn.XLOOKUP('Audit Report'!D544,Data!A:A,Data!B:B,'Audit Report'!D544)&"" | J544: ='Audit Report'!F544&"" | L544: =_xlfn.TEXTJOIN(", ", FALSE, 'Audit Report'!I544,'Audit Report'!J544,'Audit Report'!K544) -> , , | M544: ='Audit Report'!L544&"" | N544: {=IF(M544="","", _xlfn.TEXTJOIN(", ",TRUE, _xlfn.MAP(_xlfn.TEXTSPLIT(M544,","),_xlfn.LAMBDA(_xlpm.x, _xlfn.LET( _xlpm.item,TRIM(_xlpm.x), _xlpm.descCode, _xlfn.XLOOKUP(_xlpm.item,'Diagnostics Code'!$C$2:$C$500,'Diagnostics Code'!$B$2:$B$500,""), _xlpm.itadCode, IFERROR( INDEX('Diagnostics Code'!$B$2:$B$500, MATCH(TRUE, _xlfn.BYROW('Diagnostics Code'!$D$2:$D$500, _xlfn.LAMBDA(_xlpm.r,ISNUMBER(MATCH(_xlpm.item,TRIM(_xlfn.TEXTSPLIT(_xlpm.r,",")),0))) ), 0) ), ""), IF(_xlpm.descCode<>"",_xlpm.descCode,_xlpm.itadCode) ) )) ))} | R544: =_xlfn.XLOOKUP('Audit Report'!D544,Data!A:A,Data!C:C) -> #N/A | S544: ='[1]Audit Report'!N544
D545: ='Audit Report'!A545&"" -> ITD-SHR11556-W4544 | E545: ='Audit Report'!B545&"" | G545: ='Audit Report'!C545&"" | I545: =_xlfn.XLOOKUP('Audit Report'!D545,Data!A:A,Data!B:B,'Audit Report'!D545)&"" | J545: ='Audit Report'!F545&"" | L545: =_xlfn.TEXTJOIN(", ", FALSE, 'Audit Report'!I545,'Audit Report'!J545,'Audit Report'!K545) -> , , | M545: ='Audit Report'!L545&"" | N545: {=IF(M545="","", _xlfn.TEXTJOIN(", ",TRUE, _xlfn.MAP(_xlfn.TEXTSPLIT(M545,","),_xlfn.LAMBDA(_xlpm.x, _xlfn.LET( _xlpm.item,TRIM(_xlpm.x), _xlpm.descCode, _xlfn.XLOOKUP(_xlpm.item,'Diagnostics Code'!$C$2:$C$500,'Diagnostics Code'!$B$2:$B$500,""), _xlpm.itadCode, IFERROR( INDEX('Diagnostics Code'!$B$2:$B$500, MATCH(TRUE, _xlfn.BYROW('Diagnostics Code'!$D$2:$D$500, _xlfn.LAMBDA(_xlpm.r,ISNUMBER(MATCH(_xlpm.item,TRIM(_xlfn.TEXTSPLIT(_xlpm.r,",")),0))) ), 0) ), ""), IF(_xlpm.descCode<>"",_xlpm.descCode,_xlpm.itadCode) ) )) ))} | R545: =_xlfn.XLOOKUP('Audit Report'!D545,Data!A:A,Data!C:C) -> #N/A | S545: ='[1]Audit Report'!N545
D546: ='Audit Report'!A546&"" -> ITD-SHR11556-W4545 | E546: ='Audit Report'!B546&"" | G546: ='Audit Report'!C546&"" | I546: =_xlfn.XLOOKUP('Audit Report'!D546,Data!A:A,Data!B:B,'Audit Report'!D546)&"" | J546: ='Audit Report'!F546&"" | L546: =_xlfn.TEXTJOIN(", ", FALSE, 'Audit Report'!I546,'Audit Report'!J546,'Audit Report'!K546) -> , , | M546: ='Audit Report'!L546&"" | N546: {=IF(M546="","", _xlfn.TEXTJOIN(", ",TRUE, _xlfn.MAP(_xlfn.TEXTSPLIT(M546,","),_xlfn.LAMBDA(_xlpm.x, _xlfn.LET( _xlpm.item,TRIM(_xlpm.x), _xlpm.descCode, _xlfn.XLOOKUP(_xlpm.item,'Diagnostics Code'!$C$2:$C$500,'Diagnostics Code'!$B$2:$B$500,""), _xlpm.itadCode, IFERROR( INDEX('Diagnostics Code'!$B$2:$B$500, MATCH(TRUE, _xlfn.BYROW('Diagnostics Code'!$D$2:$D$500, _xlfn.LAMBDA(_xlpm.r,ISNUMBER(MATCH(_xlpm.item,TRIM(_xlfn.TEXTSPLIT(_xlpm.r,",")),0))) ), 0) ), ""), IF(_xlpm.descCode<>"",_xlpm.descCode,_xlpm.itadCode) ) )) ))} | R546: =_xlfn.XLOOKUP('Audit Report'!D546,Data!A:A,Data!C:C) -> #N/A | S546: ='[1]Audit Report'!N546
D547: ='Audit Report'!A547&"" -> ITD-SHR11556-W4546 | E547: ='Audit Report'!B547&"" | G547: ='Audit Report'!C547&"" | I547: =_xlfn.XLOOKUP('Audit Report'!D547,Data!A:A,Data!B:B,'Audit Report'!D547)&"" | J547: ='Audit Report'!F547&"" | L547: =_xlfn.TEXTJOIN(", ", FALSE, 'Audit Report'!I547,'Audit Report'!J547,'Audit Report'!K547) -> , , | M547: ='Audit Report'!L547&"" | N547: {=IF(M547="","", _xlfn.TEXTJOIN(", ",TRUE, _xlfn.MAP(_xlfn.TEXTSPLIT(M547,","),_xlfn.LAMBDA(_xlpm.x, _xlfn.LET( _xlpm.item,TRIM(_xlpm.x), _xlpm.descCode, _xlfn.XLOOKUP(_xlpm.item,'Diagnostics Code'!$C$2:$C$500,'Diagnostics Code'!$B$2:$B$500,""), _xlpm.itadCode, IFERROR( INDEX('Diagnostics Code'!$B$2:$B$500, MATCH(TRUE, _xlfn.BYROW('Diagnostics Code'!$D$2:$D$500, _xlfn.LAMBDA(_xlpm.r,ISNUMBER(MATCH(_xlpm.item,TRIM(_xlfn.TEXTSPLIT(_xlpm.r,",")),0))) ), 0) ), ""), IF(_xlpm.descCode<>"",_xlpm.descCode,_xlpm.itadCode) ) )) ))} | R547: =_xlfn.XLOOKUP('Audit Report'!D547,Data!A:A,Data!C:C) -> #N/A | S547: ='[1]Audit Report'!N547
D548: ='Audit Report'!A548&"" -> ITD-SHR11556-W4547 | E548: ='Audit Report'!B548&"" | G548: ='Audit Report'!C548&"" | I548: =_xlfn.XLOOKUP('Audit Report'!D548,Data!A:A,Data!B:B,'Audit Report'!D548)&"" | J548: ='Audit Report'!F548&"" | L548: =_xlfn.TEXTJOIN(", ", FALSE, 'Audit Report'!I548,'Audit Report'!J548,'Audit Report'!K548) -> , , | M548: ='Audit Report'!L548&"" | N548: {=IF(M548="","", _xlfn.TEXTJOIN(", ",TRUE, _xlfn.MAP(_xlfn.TEXTSPLIT(M548,","),_xlfn.LAMBDA(_xlpm.x, _xlfn.LET( _xlpm.item,TRIM(_xlpm.x), _xlpm.descCode, _xlfn.XLOOKUP(_xlpm.item,'Diagnostics Code'!$C$2:$C$500,'Diagnostics Code'!$B$2:$B$500,""), _xlpm.itadCode, IFERROR( INDEX('Diagnostics Code'!$B$2:$B$500, MATCH(TRUE, _xlfn.BYROW('Diagnostics Code'!$D$2:$D$500, _xlfn.LAMBDA(_xlpm.r,ISNUMBER(MATCH(_xlpm.item,TRIM(_xlfn.TEXTSPLIT(_xlpm.r,",")),0))) ), 0) ), ""), IF(_xlpm.descCode<>"",_xlpm.descCode,_xlpm.itadCode) ) )) ))} | R548: =_xlfn.XLOOKUP('Audit Report'!D548,Data!A:A,Data!C:C) -> #N/A | S548: ='[1]Audit Report'!N548
D549: ='Audit Report'!A549&"" -> ITD-SHR11556-W4548 | E549: ='Audit Report'!B549&"" | G549: ='Audit Report'!C549&"" | I549: =_xlfn.XLOOKUP('Audit Report'!D549,Data!A:A,Data!B:B,'Audit Report'!D549)&"" | J549: ='Audit Report'!F549&"" | L549: =_xlfn.TEXTJOIN(", ", FALSE, 'Audit Report'!I549,'Audit Report'!J549,'Audit Report'!K549) -> , , | M549: ='Audit Report'!L549&"" | N549: {=IF(M549="","", _xlfn.TEXTJOIN(", ",TRUE, _xlfn.MAP(_xlfn.TEXTSPLIT(M549,","),_xlfn.LAMBDA(_xlpm.x, _xlfn.LET( _xlpm.item,TRIM(_xlpm.x), _xlpm.descCode, _xlfn.XLOOKUP(_xlpm.item,'Diagnostics Code'!$C$2:$C$500,'Diagnostics Code'!$B$2:$B$500,""), _xlpm.itadCode, IFERROR( INDEX('Diagnostics Code'!$B$2:$B$500, MATCH(TRUE, _xlfn.BYROW('Diagnostics Code'!$D$2:$D$500, _xlfn.LAMBDA(_xlpm.r,ISNUMBER(MATCH(_xlpm.item,TRIM(_xlfn.TEXTSPLIT(_xlpm.r,",")),0))) ), 0) ), ""), IF(_xlpm.descCode<>"",_xlpm.descCode,_xlpm.itadCode) ) )) ))} | R549: =_xlfn.XLOOKUP('Audit Report'!D549,Data!A:A,Data!C:C) -> #N/A | S549: ='[1]Audit Report'!N549
D550: ='Audit Report'!A550&"" -> ITD-SHR11556-W4549 | E550: ='Audit Report'!B550&"" | G550: ='Audit Report'!C550&"" | I550: =_xlfn.XLOOKUP('Audit Report'!D550,Data!A:A,Data!B:B,'Audit Report'!D550)&"" | J550: ='Audit Report'!F550&"" | L550: =_xlfn.TEXTJOIN(", ", FALSE, 'Audit Report'!I550,'Audit Report'!J550,'Audit Report'!K550) -> , , | M550: ='Audit Report'!L550&"" | N550: {=IF(M550="","", _xlfn.TEXTJOIN(", ",TRUE, _xlfn.MAP(_xlfn.TEXTSPLIT(M550,","),_xlfn.LAMBDA(_xlpm.x, _xlfn.LET( _xlpm.item,TRIM(_xlpm.x), _xlpm.descCode, _xlfn.XLOOKUP(_xlpm.item,'Diagnostics Code'!$C$2:$C$500,'Diagnostics Code'!$B$2:$B$500,""), _xlpm.itadCode, IFERROR( INDEX('Diagnostics Code'!$B$2:$B$500, MATCH(TRUE, _xlfn.BYROW('Diagnostics Code'!$D$2:$D$500, _xlfn.LAMBDA(_xlpm.r,ISNUMBER(MATCH(_xlpm.item,TRIM(_xlfn.TEXTSPLIT(_xlpm.r,",")),0))) ), 0) ), ""), IF(_xlpm.descCode<>"",_xlpm.descCode,_xlpm.itadCode) ) )) ))} | R550: =_xlfn.XLOOKUP('Audit Report'!D550,Data!A:A,Data!C:C) -> #N/A | S550: ='[1]Audit Report'!N550
D551: ='Audit Report'!A551&"" -> ITD-SHR11556-W4550 | E551: ='Audit Report'!B551&"" | G551: ='Audit Report'!C551&"" | I551: =_xlfn.XLOOKUP('Audit Report'!D551,Data!A:A,Data!B:B,'Audit Report'!D551)&"" | J551: ='Audit Report'!F551&"" | L551: =_xlfn.TEXTJOIN(", ", FALSE, 'Audit Report'!I551,'Audit Report'!J551,'Audit Report'!K551) -> , , | M551: ='Audit Report'!L551&"" | N551: {=IF(M551="","", _xlfn.TEXTJOIN(", ",TRUE, _xlfn.MAP(_xlfn.TEXTSPLIT(M551,","),_xlfn.LAMBDA(_xlpm.x, _xlfn.LET( _xlpm.item,TRIM(_xlpm.x), _xlpm.descCode, _xlfn.XLOOKUP(_xlpm.item,'Diagnostics Code'!$C$2:$C$500,'Diagnostics Code'!$B$2:$B$500,""), _xlpm.itadCode, IFERROR( INDEX('Diagnostics Code'!$B$2:$B$500, MATCH(TRUE, _xlfn.BYROW('Diagnostics Code'!$D$2:$D$500, _xlfn.LAMBDA(_xlpm.r,ISNUMBER(MATCH(_xlpm.item,TRIM(_xlfn.TEXTSPLIT(_xlpm.r,",")),0))) ), 0) ), ""), IF(_xlpm.descCode<>"",_xlpm.descCode,_xlpm.itadCode) ) )) ))} | R551: =_xlfn.XLOOKUP('Audit Report'!D551,Data!A:A,Data!C:C) -> #N/A | S551: ='[1]Audit Report'!N551
... D598: ='Audit Report'!A598&"" -> ITD-SHR11556-W4597 | E598: ='Audit Report'!B598&"" | G598: ='Audit Report'!C598&"" | I598: =_xlfn.XLOOKUP('Audit Report'!D598,Data!A:A,Data!B:B,'Audit Report'!D598)&"" | J598: ='Audit Report'!F598&"" | L598: =_xlfn.TEXTJOIN(", ", FALSE, 'Audit Report'!I598,'Audit Report'!J598,'Audit Report'!K598) -> , , | M598: ='Audit Report'!L598&"" | N598: {=IF(M598="","", _xlfn.TEXTJOIN(", ",TRUE, _xlfn.MAP(_xlfn.TEXTSPLIT(M598,","),_xlfn.LAMBDA(_xlpm.x, _xlfn.LET( _xlpm.item,TRIM(_xlpm.x), _xlpm.descCode, _xlfn.XLOOKUP(_xlpm.item,'Diagnostics Code'!$C$2:$C$500,'Diagnostics Code'!$B$2:$B$500,""), _xlpm.itadCode, IFERROR( INDEX('Diagnostics Code'!$B$2:$B$500, MATCH(TRUE, _xlfn.BYROW('Diagnostics Code'!$D$2:$D$500, _xlfn.LAMBDA(_xlpm.r,ISNUMBER(MATCH(_xlpm.item,TRIM(_xlfn.TEXTSPLIT(_xlpm.r,",")),0))) ), 0) ), ""), IF(_xlpm.descCode<>"",_xlpm.descCode,_xlpm.itadCode) ) )) ))} | R598: =_xlfn.XLOOKUP('Audit Report'!D598,Data!A:A,Data!C:C) -> #N/A | S598: ='[1]Audit Report'!N598
...

Sheet Audit Report
A1: ITEM | B1: S.N. | C1: Asset | D1: Type | E1: Make | F1: Model | G1: Screen | H1: Year | I1: CPU | J1: RAM | K1: Disk | L1: Diagnostics | M1: Blancco result | N1: S.N. Data carrier | O1: No. Data carrier | P1: Data Destruction Method | Q1: Comments | R1: Item status | S1: Est. Value | T1: Locked or Faulty
A2: ='[1]Audit Report'!B2 -> ITD-SHR11556-W401 | B2: ='[1]Audit Report'!C2 | C2: ='[1]Audit Report'!D2 | D2: ='[1]Audit Report'!E2 | E2: ='[1]Audit Report'!F2 | F2: ='[1]Audit Report'!G2 | G2: ='[1]Audit Report'!H2 | H2: ='[1]Audit Report'!I2 | ... M2: ='[1]Audit Report'!N2 | N2: ='[1]Audit Report'!O2&"" | O2: ='[1]Audit Report'!P2&"" | P2: ='[1]Audit Report'!Q2&"" | Q2: ='[1]Audit Report'!R2&"" | R2: ='[1]Audit Report'!S2&"" | S2: ='[1]Audit Report'!T2&"" | T2: ='[1]Audit Report'!U2&""
A3: ='[1]Audit Report'!B3 -> ITD-SHR11556-W402 | B3: ='[1]Audit Report'!C3 | C3: ='[1]Audit Report'!D3 | D3: ='[1]Audit Report'!E3 | E3: ='[1]Audit Report'!F3 | F3: ='[1]Audit Report'!G3 | G3: ='[1]Audit Report'!H3 | H3: ='[1]Audit Report'!I3 | ... M3: ='[1]Audit Report'!N3 | N3: ='[1]Audit Report'!O3&"" | O3: ='[1]Audit Report'!P3&"" | P3: ='[1]Audit Report'!Q3&"" | Q3: ='[1]Audit Report'!R3&"" | R3: ='[1]Audit Report'!S3&"" | S3: ='[1]Audit Report'!T3&"" | T3: ='[1]Audit Report'!U3&""
A4: ='[1]Audit Report'!B4 -> ITD-SHR11556-W403 | B4: ='[1]Audit Report'!C4 | C4: ='[1]Audit Report'!D4 | D4: ='[1]Audit Report'!E4 | E4: ='[1]Audit Report'!F4 | F4: ='[1]Audit Report'!G4 | G4: ='[1]Audit Report'!H4 | H4: ='[1]Audit Report'!I4 | ... M4: ='[1]Audit Report'!N4 | N4: ='[1]Audit Report'!O4&"" | O4: ='[1]Audit Report'!P4&"" | P4: ='[1]Audit Report'!Q4&"" | Q4: ='[1]Audit Report'!R4&"" | R4: ='[1]Audit Report'!S4&"" | S4: ='[1]Audit Report'!T4&"" | T4: ='[1]Audit Report'!U4&""
A5: ='[1]Audit Report'!B5 -> ITD-SHR11556-W404 | B5: ='[1]Audit Report'!C5 | C5: ='[1]Audit Report'!D5 | D5: ='[1]Audit Report'!E5 | E5: ='[1]Audit Report'!F5 | F5: ='[1]Audit Report'!G5 | G5: ='[1]Audit Report'!H5 | H5: ='[1]Audit Report'!I5 | ... M5: ='[1]Audit Report'!N5 | N5: ='[1]Audit Report'!O5&"" | O5: ='[1]Audit Report'!P5&"" | P5: ='[1]Audit Report'!Q5&"" | Q5: ='[1]Audit Report'!R5&"" | R5: ='[1]Audit Report'!S5&"" | S5: ='[1]Audit Report'!T5&"" | T5: ='[1]Audit Report'!U5&""
A6: ='[1]Audit Report'!B6 -> ITD-SHR11556-W405 | B6: ='[1]Audit Report'!C6 | C6: ='[1]Audit Report'!D6 | D6: ='[1]Audit Report'!E6 | E6: ='[1]Audit Report'!F6 | F6: ='[1]Audit Report'!G6 | G6: ='[1]Audit Report'!H6 | H6: ='[1]Audit Report'!I6 | ... M6: ='[1]Audit Report'!N6 | N6: ='[1]Audit Report'!O6&"" | O6: ='[1]Audit Report'!P6&"" | P6: ='[1]Audit Report'!Q6&"" | Q6: ='[1]Audit Report'!R6&"" | R6: ='[1]Audit Report'!S6&"" | S6: ='[1]Audit Report'!T6&"" | T6: ='[1]Audit Report'!U6&""
A7: ='[1]Audit Report'!B7 -> ITD-SHR11556-W406 | B7: ='[1]Audit Report'!C7 | C7: ='[1]Audit Report'!D7 | D7: ='[1]Audit Report'!E7 | E7: ='[1]Audit Report'!F7 | F7: ='[1]Audit Report'!G7 | G7: ='[1]Audit Report'!H7 | H7: ='[1]Audit Report'!I7 | ... M7: ='[1]Audit Report'!N7 | N7: ='[1]Audit Report'!O7&"" | O7: ='[1]Audit Report'!P7&"" | P7: ='[1]Audit Report'!Q7&"" | Q7: ='[1]Audit Report'!R7&"" | R7: ='[1]Audit Report'!S7&"" | S7: ='[1]Audit Report'!T7&"" | T7: ='[1]Audit Report'!U7&""
A8: ='[1]Audit Report'!B8 -> ITD-SHR11556-W407 | B8: ='[1]Audit Report'!C8 | C8: ='[1]Audit Report'!D8 | D8: ='[1]Audit Report'!E8 | E8: ='[1]Audit Report'!F8 | F8: ='[1]Audit Report'!G8 | G8: ='[1]Audit Report'!H8 | H8: ='[1]Audit Report'!I8 | ... M8: ='[1]Audit Report'!N8 | N8: ='[1]Audit Report'!O8&"" | O8: ='[1]Audit Report'!P8&"" | P8: ='[1]Audit Report'!Q8&"" | Q8: ='[1]Audit Report'!R8&"" | R8: ='[1]Audit Report'!S8&"" | S8: ='[1]Audit Report'!T8&"" | T8: ='[1]Audit Report'!U8&""
A9: ='[1]Audit Report'!B9 -> ITD-SHR11556-W408 | B9: ='[1]Audit Report'!C9 | C9: ='[1]Audit Report'!D9 | D9: ='[1]Audit Report'!E9 | E9: ='[1]Audit Report'!F9 | F9: ='[1]Audit Report'!G9 | G9: ='[1]Audit Report'!H9 | H9: ='[1]Audit Report'!I9 | ... M9: ='[1]Audit Report'!N9 | N9: ='[1]Audit Report'!O9&"" | O9: ='[1]Audit Report'!P9&"" | P9: ='[1]Audit Report'!Q9&"" | Q9: ='[1]Audit Report'!R9&"" | R9: ='[1]Audit Report'!S9&"" | S9: ='[1]Audit Report'!T9&"" | T9: ='[1]Audit Report'!U9&""
A10: ='[1]Audit Report'!B10 -> ITD-SHR11556-W409 | B10: ='[1]Audit Report'!C10 | C10: ='[1]Audit Report'!D10 | D10: ='[1]Audit Report'!E10 | E10: ='[1]Audit Report'!F10 | F10: ='[1]Audit Report'!G10 | G10: ='[1]Audit Report'!H10 | H10: ='[1]Audit Report'!I10 | ... M10: ='[1]Audit Report'!N10 | N10: ='[1]Audit Report'!O10&"" | O10: ='[1]Audit Report'!P10&"" | P10: ='[1]Audit Report'!Q10&"" | Q10: ='[1]Audit Report'!R10&"" | R10: ='[1]Audit Report'!S10&"" | S10: ='[1]Audit Report'!T10&"" | T10: ='[1]Audit Report'!U10&""
A11: ='[1]Audit Report'!B11 -> ITD-SHR11556-W410 | B11: ='[1]Audit Report'!C11 | C11: ='[1]Audit Report'!D11 | D11: ='[1]Audit Report'!E11 | E11: ='[1]Audit Report'!F11 | F11: ='[1]Audit Report'!G11 | G11: ='[1]Audit Report'!H11 | H11: ='[1]Audit Report'!I11 | ... M11: ='[1]Audit Report'!N11 | N11: ='[1]Audit Report'!O11&"" | O11: ='[1]Audit Report'!P11&"" | P11: ='[1]Audit Report'!Q11&"" | Q11: ='[1]Audit Report'!R11&"" | R11: ='[1]Audit Report'!S11&"" | S11: ='[1]Audit Report'!T11&"" | T11: ='[1]Audit Report'!U11&""
A12: ='[1]Audit Report'!B12 -> ITD-SHR11556-W411 | B12: ='[1]Audit Report'!C12 | C12: ='[1]Audit Report'!D12 | D12: ='[1]Audit Report'!E12 | E12: ='[1]Audit Report'!F12 | F12: ='[1]Audit Report'!G12 | G12: ='[1]Audit Report'!H12 | H12: ='[1]Audit Report'!I12 | ... M12: ='[1]Audit Report'!N12 | N12: ='[1]Audit Report'!O12&"" | O12: ='[1]Audit Report'!P12&"" | P12: ='[1]Audit Report'!Q12&"" | Q12: ='[1]Audit Report'!R12&"" | R12: ='[1]Audit Report'!S12&"" | S12: ='[1]Audit Report'!T12&"" | T12: ='[1]Audit Report'!U12&""
A13: ='[1]Audit Report'!B13 -> ITD-SHR11556-W412 | B13: ='[1]Audit Report'!C13 | C13: ='[1]Audit Report'!D13 | D13: ='[1]Audit Report'!E13 | E13: ='[1]Audit Report'!F13 | F13: ='[1]Audit Report'!G13 | G13: ='[1]Audit Report'!H13 | H13: ='[1]Audit Report'!I13 | ... M13: ='[1]Audit Report'!N13 | N13: ='[1]Audit Report'!O13&"" | O13: ='[1]Audit Report'!P13&"" | P13: ='[1]Audit Report'!Q13&"" | Q13: ='[1]Audit Report'!R13&"" | R13: ='[1]Audit Report'!S13&"" | S13: ='[1]Audit Report'!T13&"" | T13: ='[1]Audit Report'!U13&""
... A650: ='[1]Audit Report'!B650 -> ITD-SHR11556-W4649 | B650: ='[1]Audit Report'!C650 | C650: ='[1]Audit Report'!D650 | D650: ='[1]Audit Report'!E650 | E650: ='[1]Audit Report'!F650 | F650: ='[1]Audit Report'!G650 | G650: ='[1]Audit Report'!H650 | H650: ='[1]Audit Report'!I650 | ... M650: ='[1]Audit Report'!N650 | N650: ='[1]Audit Report'!O650&"" | O650: ='[1]Audit Report'!P650&"" | P650: ='[1]Audit Report'!Q650&"" | Q650: ='[1]Audit Report'!R650&"" | R650: ='[1]Audit Report'!S650&"" | S650: ='[1]Audit Report'!T650&"" | T650: ='[1]Audit Report'!U650&""

Sheet Data
A1: Type | B1: Category | C1: Weight (KG)
A2: Laptop | B2: Notebook | C2: 2
A3: Desktop SFF | B3: PC | C3: 6
A4: Desktop Tower | B4: PC | C4: 9
A5: Server | B5: Server | C5: 15
A6: Desktop Mini | B6: PC | C6: 1.5
A7: All-in-One | B7: All in One System | C7: 9
A8: Monitor | B8: Monitor TFT | C8: 5.5
A9: TV | B9: Monitor TFT | C9: 8
A10: Projector | B10: Projector & Beamer | C10: 6
A11: Keyboard | B11: Other | C11: 0.2
A12: Mouse | B12: Other | C12: 0.1
A13: Webcam | B13: Other | C13: 0.1
... A27: Network equipment | B27: Network Equipment | C27: 4.5
A28: Other | B28: Other
A29: Loose SSD | B29: Additional Data Carrier | C29: 0.1
A30: Loose HDD | B30: Additional Data Carrier | C30: 0.1
A31: Loose NVME | B31: Additional Data Carrier | C31: 0.1

Sheet Diagnostics Code
A1: category | B1: code | C1: description | D1: ITAD description
A2: Notebook | B2: LPT001 | C2: a/c adapter defect
A3: Notebook | B3: LPT002 | C3: a/c adapter missing
A4: Notebook | B4: LPT010 | C4: backlight defect
A5: Notebook | B5: LPT012 | C5: badge missing
A6: Notebook | B6: LPT013 | C6: battery bay defect
A7: Notebook | B7: LPT014 | C7: battery defect | D7: Battery C,Battery D
A8: Notebook | B8: LPT016 | C8: battery missing
A9: Notebook | B9: LPT018 | C9: bezel defect
A10: Notebook | B10: LPT019 | C10: bezel missing
A11: Notebook | B11: LPT020 | C11: bios failure
A12: Notebook | B12: LPT027 | C12: cable missing
A13: Notebook | B13: LPT030 | C13: case cracked major | D13: Broken chassis,Chassis broken
A14: Notebook | B14: LPT031 | C14: case cracked minor
A15: Notebook | B15: LPT032 | C15: case dent major | D15: Chassis damage C,Chassis damage D
A16: Notebook | B16: LPT033 | C16: case dent minor | D16: Chassis damage B
A17: Notebook | B17: LPT034 | C17: case discoloration | D17: Label marks B,Label marks C,Label marks D
A18: Notebook | B18: LPT037 | C18: case scratched major
A19: Notebook | B19: LPT038 | C19: case scratched minor
A20: Notebook | B20: LPT040 | C20: charger entry point defect | D20: Charging port defect
A21: Notebook | B21: LPT041 | C21: control panel defect
A22: Notebook | B22: LPT042 | C22: control panel missing
A23: Notebook | B23: LPT043 | C23: cover defect
A24: Notebook | B24: LPT044 | C24: cover missing
A25: Notebook | B25: LPT046 | C25: cpu missing
A26: Notebook | B26: LPT051 | C26: display brigthness major
A27: Notebook | B27: LPT052 | C27: display brigthness minor
A28: Notebook | B28: LPT053 | C28: display burnt-in
A29: Notebook | B29: LPT054 | C29: display coating major
A30: Notebook | B30: LPT055 | C30: display coating minor
A31: Notebook | B31: LPT056 | C31: display colour major | D31: Display C,Display D
A32: Notebook | B32: LPT057 | C32: display colour minor | D32: Display B
A33: Notebook | B33: LPT058 | C33: display cracked | D33: Broken screen
A34: Notebook | B34: LPT063 | C34: display flickering
A35: Notebook | B35: LPT067 | C35: display mark bright major | D35: LED spot C,LED spot D
A36: Notebook | B36: LPT068 | C36: display mark bright minor | D36: LED spot B
A37: Notebook | B37: LPT069 | C37: display mark dark major
A38: Notebook | B38: LPT070 | C38: display mark dark minor
A39: Notebook | B39: LPT071 | C39: display missing
A40: Notebook | B40: LPT072 | C40: display pixel failure major | D40: Screen defect
...
